<?xml version="1.0"?>
<robot name="vacuumcleaner">
  <link name="base_footprint"/>	 
  <link name="base_link">
    <visual>
      <geometry>
        <box size="0.4 0.15 0.1"/>
      </geometry>
    </visual>
    <collision>
      <geometry>
        <box size="0.4 0.15 0.1"/>
      </geometry>
   </collision>
    <inertial>
	    <mass value="5"/>
	          <inertia ixx="0.0395416666667" ixy="0" ixz="0" iyy="0.106208333333" iyz="0" izz="0.106208333333"/>

     </inertial>
    <collision name="caster_front_collision">
      <origin rpy="0 0 0" xyz="0.19 0 -0.06"/>
      <geometry>
        <sphere radius="0.01"/>
      </geometry>
      <surface>
        <friction>
          <ode>
            <mu>0</mu>
            <mu2>0</mu2>
            <slip1>1.0</slip1>
            <slip2>1.0</slip2>
          </ode>
        </friction>
      </surface>
    </collision>
    <visual name="caster_front_visual">
      <origin rpy="0 0 0" xyz="0.19 0 -0.06"/>
      <geometry>
        <sphere radius="0.01"/>
      </geometry>
    </visual>
    </link>

  <link name="base_scan">
    <visual>
      <geometry>
        <sphere radius="0.05"/>
      </geometry>
      <material name="white"/>
    </visual>

    <collision>
      <geometry>
        <sphere radius="0.05"/>
      </geometry>
    </collision>
    <inertial>
      <mass value="0.1" />
      <origin rpy="0 0 0" xyz="-0.15 0 +0.15" />
      <inertia ixx="0.0005" ixy="0" ixz="0" iyy="0.00" iyz="0" izz="0.001" />
    </inertial>


 </link>

  <link name="link_right_wheel">
    <inertial>
      <mass value="0.2"/>
      <origin rpy="0 1.5707 1.5707" xyz="0 0 0"/>
      <inertia ixx="0.00052666666" ixy="0" ixz="0" iyy="0.00052666666" iyz="0" izz="0.001"/>
    </inertial>       

    <collision name="link_right_wheel_collision">
      <origin rpy="0 1.5707 1.5707" xyz="0 0 0"/>
      <geometry>
        <cylinder length="0.04" radius="0.05"/>
      </geometry>
    </collision>
    <visual name="link_right_wheel_visual">
      <origin rpy="0 1.5707 1.5707" xyz="0 0 0"/>
      <geometry>
        <cylinder length="0.04" radius="0.05"/>
      </geometry>
    </visual>
  </link>


  <link name="link_left_wheel">
    <inertial>
      <mass value="0.2"/>
      <origin rpy="0 1.5707 1.5707" xyz="0 0 0"/>
      <inertia ixx="0.00052666666" ixy="0" ixz="0" iyy="0.00052666666" iyz="0" izz="0.001"/>
    </inertial>
       

	  <collision name="link_left_wheel_collision">
      <origin rpy="0 1.5707 1.5707" xyz="0 0 0"/>
      <geometry>
        <cylinder length="0.04" radius="0.05"/>
      </geometry>
    </collision>
    <visual name="link_left_wheel_visual">
      <origin rpy="0 1.5707 1.5707" xyz="0 0 0"/>
      <geometry>
        <cylinder length="0.04" radius="0.05"/>
      </geometry>
    </visual>
  </link>


  <joint name="joint_right_wheel" type="continuous">
    <origin rpy="0 0 0" xyz="-0.1 0.10 -0.02"/>
    <child link="link_right_wheel"/>
    <parent link="base_link"/>
    <axis rpy="0 0 0" xyz="0 1 0"/>
    <limit effort="10000" velocity="1000"/>
  </joint>
  <joint name="joint_left_wheel" type="continuous">
    <origin rpy="0 0 0" xyz="-0.1 -0.10 -0.02"/>
    <child link="link_left_wheel"/>
    <parent link="base_link"/>
    <axis rpy="0 0 0" xyz="0 1 0"/>
    <limit effort="10000" velocity="1000"/>
  </joint>

   <joint name="base_joint" type="fixed">
    <parent link="base_footprint"/>
    <child link="base_link" />
    <origin xyz="0 0 0" rpy="0 0 0"/>
  </joint>

  <joint name="base_scan_joint" type="fixed">
   <child link="base_scan" />
   <parent link="base_link" />
   <origin xyz="0 0 0.05"/>
  </joint>
  <gazebo reference="base_scan">
    <sensor name="hls_lfcd_lds" type="ray">
        <always_on>true</always_on>
        <visualize>true</visualize>
        <update_rate>5</update_rate>
        <ray>
          <scan>
            <horizontal>
              <samples>360</samples>
              <resolution>1.000000</resolution>
              <min_angle>0.000000</min_angle>
              <max_angle>6.280000</max_angle>
            </horizontal>
          </scan>
          <range>
            <min>0.120000</min>
            <max>3.5</max>
            <resolution>0.015000</resolution>
          </range>
          <noise>
            <type>gaussian</type>
            <mean>0.0</mean>
            <stddev>0.01</stddev>
          </noise>
        </ray>
        <plugin name="turtlebot3_laserscan" filename="libgazebo_ros_ray_sensor.so">
          <ros>
            <!-- <namespace>/tb3</namespace> -->
            <argument>~/out:=scan</argument>
          </ros>
          <output_type>sensor_msgs/LaserScan</output_type>
          <frame_name>base_scan</frame_name>
        </plugin>
      </sensor>
  </gazebo>
</robot>
